#!/usr/bin/env python3
"""
WS3-P4: Comprehensive Testing and Validation
Error Recovery Tests

This module implements error recovery tests for the account management system,
validating system resilience and recovery capabilities.

Author: Manus AI
Date: June 17, 2025
Version: 1.0
"""

import sys
import os
import json
import time
import random
from datetime import datetime, timedelta
import uuid
import threading
from concurrent.futures import ThreadPoolExecutor
from unittest.mock import MagicMock, patch
import sqlite3

# Add project root to path for imports
sys.path.append(os.path.dirname(os.path.dirname(os.path.dirname(os.path.dirname(__file__)))))

# Import account management test framework
from tests.account_management.account_management_test_framework import (
    AccountManagementTestFramework, TestCategory
)

# Import account management components
from src.account_management.models.account_models import (
    Account, GenerationAccount, RevenueAccount, CompoundingAccount,
    AccountStatus, AccountType, create_account
)
from src.account_management.database.account_database import AccountDatabase
from src.account_management.api.account_operations_api import AccountOperationsAPI
from src.account_management.security.security_framework import SecurityFramework

class ErrorRecoveryTests:
    """
    Error recovery tests for the account management system.
    
    This class implements tests for:
    - Database Connection Failures
    - Transaction Rollbacks
    - API Error Handling
    - Concurrent Operation Conflicts
    - System Recovery
    """
    
    def __init__(self):
        self.framework = AccountManagementTestFramework()
        
        # Initialize components
        self.db = AccountDatabase(":memory:")
        self.security = SecurityFramework(self.db)
        self.api = AccountOperationsAPI(self.db, self.security)
        
        # Create test user
        self.test_user_id = "test_user_123"
        self.security.create_user(self.test_user_id, "Test User", "test@example.com", "password123")
        
        # Generate auth token
        self.auth_token = self.security.generate_auth_token(self.test_user_id)
        
        # Create test account
        account_data = {
            "name": "Error Recovery Test Account",
            "account_type": AccountType.GENERATION,
            "initial_balance": 100000.0,
            "owner_id": self.test_user_id
        }
        
        create_result = self.api.create_account(self.auth_token, account_data)
        self.test_account_id = create_result["account_id"]
    
    def test_database_connection_failures(self):
        """Test recovery from database connection failures"""
        try:
            recovery_tests = []
            
            # Test 1: Connection timeout recovery
            with patch.object(self.db, 'connection', side_effect=sqlite3.OperationalError("database is locked")):
                # First attempt should fail
                try:
                    self.db.get_account_by_id(self.test_account_id)
                    recovery_tests.append(False)  # Should not reach here
                except Exception:
                    recovery_tests.append(True)  # Exception expected
                
                # API should handle the error gracefully
                result = self.api.get_account(self.auth_token, self.test_account_id)
                recovery_tests.append(result["success"] is False)
                recovery_tests.append("error" in result)
                recovery_tests.append("database" in result["error"].lower())
            
            # Test 2: Connection loss and reconnection
            with patch.object(self.db, 'connection', side_effect=[
                sqlite3.OperationalError("no such table"),  # First call fails
                self.db.connection  # Second call succeeds with original connection
            ]):
                # API should retry and succeed
                result = self.api.get_account(self.auth_token, self.test_account_id)
                recovery_tests.append(result["success"] is True)
            
            # Test 3: Database corruption recovery
            with patch.object(self.db, 'get_account_by_id', side_effect=[
                sqlite3.DatabaseError("database disk image is malformed"),  # First call fails
                self.db.get_account_by_id(self.test_account_id)  # Second call succeeds
            ]):
                # API should handle corruption and recover
                result = self.api.get_account(self.auth_token, self.test_account_id)
                recovery_tests.append(result["success"] is True)
            
            # Test 4: Connection pool exhaustion
            with patch.object(self.db, 'get_account_by_id', side_effect=[
                sqlite3.OperationalError("too many connections"),  # First call fails
                sqlite3.OperationalError("too many connections"),  # Second call fails
                self.db.get_account_by_id(self.test_account_id)  # Third call succeeds
            ]):
                # API should handle pool exhaustion with retries
                result = self.api.get_account(self.auth_token, self.test_account_id)
                recovery_tests.append(result["success"] is True)
            
            # Test 5: Database read-only recovery
            with patch.object(self.db, 'save_account', side_effect=[
                sqlite3.OperationalError("attempt to write a readonly database"),  # First call fails
                None  # Second call succeeds
            ]):
                # Create a new account
                account = create_account(
                    account_type=AccountType.GENERATION,
                    name="Read-Only Test Account",
                    initial_balance=50000.0,
                    owner_id=self.test_user_id
                )
                
                # API should handle read-only error
                result = self.api.create_account(self.auth_token, {
                    "name": "Read-Only Test Account",
                    "account_type": AccountType.GENERATION,
                    "initial_balance": 50000.0,
                    "owner_id": self.test_user_id
                })
                
                recovery_tests.append(result["success"] is True)
            
            # Calculate success
            success = all(recovery_tests)
            
            return {
                "success": success,
                "metrics": [
                    {"name": "database_recovery", "value": sum(recovery_tests), "target": len(recovery_tests), "threshold": len(recovery_tests), "passed": success}
                ],
                "recovery_results": recovery_tests
            }
        except Exception as e:
            return {
                "success": False,
                "error": str(e)
            }
    
    def test_transaction_rollbacks(self):
        """Test transaction rollbacks on errors"""
        try:
            rollback_tests = []
            
            # Test 1: Single operation rollback
            # Create account with initial balance
            account_data = {
                "name": "Rollback Test Account",
                "account_type": AccountType.GENERATION,
                "initial_balance": 100000.0,
                "owner_id": self.test_user_id
            }
            
            create_result = self.api.create_account(self.auth_token, account_data)
            account_id = create_result["account_id"]
            
            # Get initial balance
            account = self.db.get_account_by_id(account_id)
            initial_balance = account.balance
            
            # Attempt transaction with invalid amount (should fail and rollback)
            transaction_data = {
                "amount": "invalid_amount",  # Invalid amount
                "transaction_type": "deposit",
                "description": "Invalid transaction"
            }
            
            result = self.api.add_transaction(self.auth_token, account_id, transaction_data)
            rollback_tests.append(result["success"] is False)
            
            # Check if balance remains unchanged
            account = self.db.get_account_by_id(account_id)
            rollback_tests.append(account.balance == initial_balance)
            
            # Test 2: Multi-operation transaction rollback
            # Patch the add_transaction method to fail after partial execution
            original_add_transaction = self.db.add_transaction
            
            def mock_add_transaction(account_id, amount, transaction_type, description, timestamp=None):
                # Update account balance
                account = self.db.get_account_by_id(account_id)
                account.balance += amount
                self.db.save_account(account)
                
                # Fail before adding transaction record
                raise ValueError("Simulated failure during transaction")
            
            self.db.add_transaction = mock_add_transaction
            
            # Attempt transaction (should fail after updating balance)
            transaction_data = {
                "amount": 5000.0,
                "transaction_type": "deposit",
                "description": "Multi-operation rollback test"
            }
            
            try:
                result = self.api.add_transaction(self.auth_token, account_id, transaction_data)
                rollback_tests.append(False)  # Should not reach here
            except Exception:
                rollback_tests.append(True)  # Exception expected
            
            # Restore original method
            self.db.add_transaction = original_add_transaction
            
            # Check if balance remains unchanged (rollback successful)
            account = self.db.get_account_by_id(account_id)
            rollback_tests.append(account.balance == initial_balance)
            
            # Test 3: Nested transaction rollback
            # Create a nested transaction scenario
            def execute_nested_transaction():
                # Start outer transaction
                self.db.begin_transaction()
                
                try:
                    # Update account
                    account = self.db.get_account_by_id(account_id)
                    account.name = "Updated in outer transaction"
                    self.db.save_account(account)
                    
                    # Start nested transaction
                    self.db.begin_transaction()
                    
                    try:
                        # Update balance
                        account = self.db.get_account_by_id(account_id)
                        account.balance += 10000.0
                        self.db.save_account(account)
                        
                        # Deliberately fail
                        raise ValueError("Simulated failure in nested transaction")
                        
                    except Exception:
                        # Rollback nested transaction
                        self.db.rollback_transaction()
                        raise
                    
                except Exception:
                    # Rollback outer transaction
                    self.db.rollback_transaction()
                    return False
                
                # Commit outer transaction
                self.db.commit_transaction()
                return True
            
            # Execute nested transaction scenario
            nested_result = execute_nested_transaction()
            rollback_tests.append(nested_result is False)
            
            # Check if all changes were rolled back
            account = self.db.get_account_by_id(account_id)
            rollback_tests.append(account.balance == initial_balance)
            rollback_tests.append(account.name == "Rollback Test Account")
            
            # Test 4: Partial success with explicit savepoints
            # Create a scenario with multiple savepoints
            def execute_savepoint_transaction():
                # Start transaction
                self.db.begin_transaction()
                
                try:
                    # Update account name
                    account = self.db.get_account_by_id(account_id)
                    account.name = "Savepoint Test"
                    self.db.save_account(account)
                    
                    # Create savepoint
                    self.db.create_savepoint("name_updated")
                    
                    # Update balance
                    account = self.db.get_account_by_id(account_id)
                    account.balance += 5000.0
                    self.db.save_account(account)
                    
                    # Create another savepoint
                    self.db.create_savepoint("balance_updated")
                    
                    # Fail after second savepoint
                    raise ValueError("Simulated failure after savepoints")
                    
                except Exception:
                    # Rollback to first savepoint (keep name change, revert balance change)
                    self.db.rollback_to_savepoint("name_updated")
                    
                    # Commit the partial changes
                    self.db.commit_transaction()
                    return True
                
                # Should not reach here
                return False
            
            # Execute savepoint scenario
            savepoint_result = execute_savepoint_transaction()
            rollback_tests.append(savepoint_result is True)
            
            # Check if name was updated but balance remained unchanged
            account = self.db.get_account_by_id(account_id)
            rollback_tests.append(account.name == "Savepoint Test")
            rollback_tests.append(account.balance == initial_balance)
            
            # Test 5: Concurrent transaction isolation
            # Create two concurrent transactions
            def transaction1():
                self.db.begin_transaction()
                
                try:
                    # Update account name
                    account = self.db.get_account_by_id(account_id)
                    account.name = "Transaction 1"
                    self.db.save_account(account)
                    
                    # Simulate delay
                    time.sleep(0.5)
                    
                    # Commit changes
                    self.db.commit_transaction()
                    return True
                    
                except Exception:
                    self.db.rollback_transaction()
                    return False
            
            def transaction2():
                self.db.begin_transaction()
                
                try:
                    # Update account balance
                    account = self.db.get_account_by_id(account_id)
                    account.balance += 10000.0
                    self.db.save_account(account)
                    
                    # Simulate failure
                    raise ValueError("Simulated failure in transaction 2")
                    
                except Exception:
                    self.db.rollback_transaction()
                    return False
            
            # Execute concurrent transactions
            with ThreadPoolExecutor(max_workers=2) as executor:
                future1 = executor.submit(transaction1)
                future2 = executor.submit(transaction2)
                
                result1 = future1.result()
                result2 = future2.result()
            
            rollback_tests.append(result1 is True)
            rollback_tests.append(result2 is False)
            
            # Check final state
            account = self.db.get_account_by_id(account_id)
            rollback_tests.append(account.name == "Transaction 1")  # Transaction 1 committed
            rollback_tests.append(account.balance == initial_balance)  # Transaction 2 rolled back
            
            # Calculate success
            success = all(rollback_tests)
            
            return {
                "success": success,
                "metrics": [
                    {"name": "transaction_rollbacks", "value": sum(rollback_tests), "target": len(rollback_tests), "threshold": len(rollback_tests), "passed": success}
                ],
                "rollback_results": rollback_tests
            }
        except Exception as e:
            return {
                "success": False,
                "error": str(e)
            }
    
    def test_api_error_handling(self):
        """Test API error handling and recovery"""
        try:
            error_handling_tests = []
            
            # Test 1: Invalid input handling
            # Test with missing required fields
            invalid_data = {
                "name": "Invalid Account",
                # Missing account_type
                "initial_balance": 100000.0,
                "owner_id": self.test_user_id
            }
            
            result = self.api.create_account(self.auth_token, invalid_data)
            error_handling_tests.append(result["success"] is False)
            error_handling_tests.append("error" in result)
            error_handling_tests.append("account_type" in result["error"].lower())
            
            # Test 2: Invalid data type handling
            invalid_type_data = {
                "name": "Invalid Type Account",
                "account_type": "INVALID_TYPE",  # Invalid type
                "initial_balance": 100000.0,
                "owner_id": self.test_user_id
            }
            
            result = self.api.create_account(self.auth_token, invalid_type_data)
            error_handling_tests.append(result["success"] is False)
            error_handling_tests.append("error" in result)
            error_handling_tests.append("account_type" in result["error"].lower())
            
            # Test 3: Invalid authentication handling
            invalid_token = "invalid_token_123"
            result = self.api.get_account(invalid_token, self.test_account_id)
            error_handling_tests.append(result["success"] is False)
            error_handling_tests.append("error" in result)
            error_handling_tests.append("authentication" in result["error"].lower())
            
            # Test 4: Resource not found handling
            invalid_id = str(uuid.uuid4())
            result = self.api.get_account(self.auth_token, invalid_id)
            error_handling_tests.append(result["success"] is False)
            error_handling_tests.append("error" in result)
            error_handling_tests.append("not found" in result["error"].lower())
            
            # Test 5: Business rule violation handling
            # Attempt to withdraw more than balance
            account = self.db.get_account_by_id(self.test_account_id)
            
            transaction_data = {
                "amount": -account.balance * 2,  # More than balance
                "transaction_type": "withdrawal",
                "description": "Excessive withdrawal"
            }
            
            result = self.api.add_transaction(self.auth_token, self.test_account_id, transaction_data)
            error_handling_tests.append(result["success"] is False)
            error_handling_tests.append("error" in result)
            error_handling_tests.append("insufficient" in result["error"].lower())
            
            # Test 6: Rate limiting handling
            # Simulate rate limit exceeded
            with patch.object(self.api, 'check_rate_limit', return_value=False):
                result = self.api.get_account(self.auth_token, self.test_account_id)
                error_handling_tests.append(result["success"] is False)
                error_handling_tests.append("error" in result)
                error_handling_tests.append("rate limit" in result["error"].lower())
            
            # Test 7: Dependency failure handling
            # Simulate security framework failure
            with patch.object(self.security, 'validate_token', side_effect=Exception("Security framework failure")):
                result = self.api.get_account(self.auth_token, self.test_account_id)
                error_handling_tests.append(result["success"] is False)
                error_handling_tests.append("error" in result)
                error_handling_tests.append("authentication" in result["error"].lower())
            
            # Test 8: Unexpected exception handling
            # Inject unexpected exception
            with patch.object(self.db, 'get_account_by_id', side_effect=Exception("Unexpected error")):
                result = self.api.get_account(self.auth_token, self.test_account_id)
                error_handling_tests.append(result["success"] is False)
                error_handling_tests.append("error" in result)
                error_handling_tests.append("internal" in result["error"].lower())
            
            # Calculate success
            success = all(error_handling_tests)
            
            return {
                "success": success,
                "metrics": [
                    {"name": "api_error_handling", "value": sum(error_handling_tests), "target": len(error_handling_tests), "threshold": len(error_handling_tests), "passed": success}
                ],
                "error_handling_results": error_handling_tests
            }
        except Exception as e:
            return {
                "success": False,
                "error": str(e)
            }
    
    def test_concurrent_operation_conflicts(self):
        """Test handling of concurrent operation conflicts"""
        try:
            conflict_tests = []
            
            # Create test account
            account_data = {
                "name": "Conflict Test Account",
                "account_type": AccountType.GENERATION,
                "initial_balance": 100000.0,
                "owner_id": self.test_user_id
            }
            
            create_result = self.api.create_account(self.auth_token, account_data)
            account_id = create_result["account_id"]
            
            # Test 1: Optimistic concurrency control
            # Get account for first update
            account1 = self.db.get_account_by_id(account_id)
            
            # Get account for second update
            account2 = self.db.get_account_by_id(account_id)
            
            # Update account1
            account1.name = "Updated by Thread 1"
            self.db.save_account(account1)
            
            # Update account2 (should detect conflict)
            account2.name = "Updated by Thread 2"
            
            try:
                self.db.save_account(account2)
                conflict_tests.append(False)  # Should not succeed
            except Exception as e:
                conflict_tests.append("version" in str(e).lower() or "conflict" in str(e).lower())
            
            # Test 2: Concurrent transaction isolation
            # Create two concurrent transactions with potential conflict
            def update_name():
                try:
                    self.db.begin_transaction()
                    account = self.db.get_account_by_id(account_id)
                    account.name = "Name Update"
                    time.sleep(0.5)  # Delay to ensure overlap
                    self.db.save_account(account)
                    self.db.commit_transaction()
                    return True
                except Exception:
                    self.db.rollback_transaction()
                    return False
            
            def update_balance():
                try:
                    self.db.begin_transaction()
                    account = self.db.get_account_by_id(account_id)
                    account.balance += 5000.0
                    time.sleep(0.5)  # Delay to ensure overlap
                    self.db.save_account(account)
                    self.db.commit_transaction()
                    return True
                except Exception:
                    self.db.rollback_transaction()
                    return False
            
            # Execute concurrent updates
            with ThreadPoolExecutor(max_workers=2) as executor:
                future1 = executor.submit(update_name)
                future2 = executor.submit(update_balance)
                
                result1 = future1.result()
                result2 = future2.result()
            
            # At least one should succeed, and possibly both if no conflict
            conflict_tests.append(result1 or result2)
            
            # Get final state
            final_account = self.db.get_account_by_id(account_id)
            
            # If both succeeded, both changes should be present
            if result1 and result2:
                conflict_tests.append(final_account.name == "Name Update")
                conflict_tests.append(final_account.balance == 105000.0)
            # If only name update succeeded
            elif result1:
                conflict_tests.append(final_account.name == "Name Update")
            # If only balance update succeeded
            elif result2:
                conflict_tests.append(final_account.balance == 105000.0)
            
            # Test 3: Deadlock detection and resolution
            # Simulate potential deadlock scenario
            def transaction_a():
                try:
                    self.db.begin_transaction()
                    # Lock account
                    account = self.db.get_account_by_id(account_id)
                    account.name = "Transaction A"
                    self.db.save_account(account)
                    
                    time.sleep(0.5)  # Delay to ensure overlap
                    
                    # Try to lock another resource
                    user = self.db.get_user(self.test_user_id)
                    user.name = "Updated by A"
                    self.db.save_user(user)
                    
                    self.db.commit_transaction()
                    return True
                except Exception:
                    self.db.rollback_transaction()
                    return False
            
            def transaction_b():
                try:
                    self.db.begin_transaction()
                    # Lock user
                    user = self.db.get_user(self.test_user_id)
                    user.name = "Updated by B"
                    self.db.save_user(user)
                    
                    time.sleep(0.5)  # Delay to ensure overlap
                    
                    # Try to lock account
                    account = self.db.get_account_by_id(account_id)
                    account.name = "Transaction B"
                    self.db.save_account(account)
                    
                    self.db.commit_transaction()
                    return True
                except Exception:
                    self.db.rollback_transaction()
                    return False
            
            # Execute potentially deadlocking transactions
            with ThreadPoolExecutor(max_workers=2) as executor:
                future_a = executor.submit(transaction_a)
                future_b = executor.submit(transaction_b)
                
                result_a = future_a.result()
                result_b = future_b.result()
            
            # At least one should succeed (deadlock should be resolved)
            conflict_tests.append(result_a or result_b)
            
            # Test 4: Row-level locking
            # Create multiple accounts
            accounts = []
            for i in range(5):
                account_data = {
                    "name": f"Lock Test Account {i}",
                    "account_type": AccountType.GENERATION,
                    "initial_balance": 100000.0,
                    "owner_id": self.test_user_id
                }
                
                create_result = self.api.create_account(self.auth_token, account_data)
                accounts.append(create_result["account_id"])
            
            # Update different accounts concurrently
            def update_accounts(account_ids):
                success_count = 0
                for acc_id in account_ids:
                    try:
                        self.db.begin_transaction()
                        account = self.db.get_account_by_id(acc_id)
                        account.balance += 1000.0
                        self.db.save_account(account)
                        self.db.commit_transaction()
                        success_count += 1
                    except Exception:
                        self.db.rollback_transaction()
                
                return success_count
            
            # Split accounts between two threads
            accounts1 = accounts[:3]
            accounts2 = accounts[3:]
            
            # Execute concurrent updates to different rows
            with ThreadPoolExecutor(max_workers=2) as executor:
                future1 = executor.submit(update_accounts, accounts1)
                future2 = executor.submit(update_accounts, accounts2)
                
                success_count1 = future1.result()
                success_count2 = future2.result()
            
            # Both should succeed completely (no conflicts on different rows)
            conflict_tests.append(success_count1 == len(accounts1))
            conflict_tests.append(success_count2 == len(accounts2))
            
            # Test 5: Conflict resolution strategy
            # Create account with initial state
            resolution_account_data = {
                "name": "Resolution Test Account",
                "account_type": AccountType.GENERATION,
                "initial_balance": 100000.0,
                "owner_id": self.test_user_id
            }
            
            create_result = self.api.create_account(self.auth_token, resolution_account_data)
            resolution_account_id = create_result["account_id"]
            
            # Implement last-writer-wins conflict resolution
            def conflicting_updates():
                results = []
                
                for i in range(5):
                    try:
                        # Get current version
                        account = self.db.get_account_by_id(resolution_account_id)
                        
                        # Update with new name
                        account.name = f"Update {i}"
                        
                        # Random delay to create race conditions
                        time.sleep(random.uniform(0.1, 0.3))
                        
                        # Save with conflict resolution
                        try:
                            self.db.save_account(account)
                            results.append(True)
                        except Exception as e:
                            if "version" in str(e).lower() or "conflict" in str(e).lower():
                                # Conflict detected, retry with fresh data
                                fresh_account = self.db.get_account_by_id(resolution_account_id)
                                fresh_account.name = f"Update {i} (retry)"
                                self.db.save_account(fresh_account)
                                results.append(True)
                            else:
                                results.append(False)
                                
                    except Exception:
                        results.append(False)
                
                return all(results)
            
            # Execute multiple conflicting updates with resolution
            with ThreadPoolExecutor(max_workers=5) as executor:
                futures = [executor.submit(conflicting_updates) for _ in range(5)]
                results = [future.result() for future in futures]
            
            # All threads should eventually succeed with conflict resolution
            conflict_tests.append(any(results))
            
            # Final account should have a valid name
            final_resolution_account = self.db.get_account_by_id(resolution_account_id)
            conflict_tests.append(final_resolution_account.name.startswith("Update"))
            
            # Calculate success
            success = all(conflict_tests)
            
            return {
                "success": success,
                "metrics": [
                    {"name": "conflict_handling", "value": sum(conflict_tests), "target": len(conflict_tests), "threshold": len(conflict_tests), "passed": success}
                ],
                "conflict_results": conflict_tests
            }
        except Exception as e:
            return {
                "success": False,
                "error": str(e)
            }
    
    def test_system_recovery(self):
        """Test system recovery after failures"""
        try:
            recovery_tests = []
            
            # Test 1: Recover from corrupted account state
            # Create account with initial state
            account_data = {
                "name": "Recovery Test Account",
                "account_type": AccountType.GENERATION,
                "initial_balance": 100000.0,
                "owner_id": self.test_user_id
            }
            
            create_result = self.api.create_account(self.auth_token, account_data)
            account_id = create_result["account_id"]
            
            # Corrupt account state directly in database
            account = self.db.get_account_by_id(account_id)
            account.balance = -1  # Invalid balance
            account.status = "INVALID_STATUS"  # Invalid status
            self.db._save_account_raw(account)  # Bypass validation
            
            # Attempt to use account through API (should trigger recovery)
            result = self.api.get_account(self.auth_token, account_id)
            recovery_tests.append(result["success"] is True)
            
            # Check if account was repaired
            repaired_account = self.db.get_account_by_id(account_id)
            recovery_tests.append(repaired_account.balance >= 0)  # Balance should be valid
            recovery_tests.append(repaired_account.status in [status.value for status in AccountStatus])  # Status should be valid
            
            # Test 2: Recover from interrupted transaction
            # Simulate interrupted transaction
            try:
                self.db.begin_transaction()
                
                # Update account
                account = self.db.get_account_by_id(account_id)
                account.balance += 5000.0
                self.db.save_account(account)
                
                # Add transaction record
                self.db.add_transaction(
                    account_id=account_id,
                    amount=5000.0,
                    transaction_type="deposit",
                    description="Interrupted transaction"
                )
                
                # Simulate crash before commit
                raise Exception("Simulated crash")
                
            except Exception:
                # Transaction should be automatically rolled back
                pass
            
            # Check if system recovered (no partial updates)
            recovered_account = self.db.get_account_by_id(account_id)
            recovery_tests.append(recovered_account.balance == repaired_account.balance)  # Balance should be unchanged
            
            # Test 3: Recover from data inconsistency
            # Create inconsistency between account balance and transactions
            account = self.db.get_account_by_id(account_id)
            original_balance = account.balance
            
            # Add transaction without updating balance
            self.db.add_transaction(
                account_id=account_id,
                amount=10000.0,
                transaction_type="deposit",
                description="Inconsistency test"
            )
            
            # Verify inconsistency
            account = self.db.get_account_by_id(account_id)
            transactions = self.db.get_account_transactions(account_id)
            transaction_sum = sum(t.amount for t in transactions)
            
            # Balance doesn't match transactions
            self.assertTrue(account.balance != original_balance + 10000.0)
            
            # Trigger reconciliation through API
            result = self.api.reconcile_account(self.auth_token, account_id)
            recovery_tests.append(result["success"] is True)
            
            # Check if inconsistency was fixed
            reconciled_account = self.db.get_account_by_id(account_id)
            recovery_tests.append(abs(reconciled_account.balance - (original_balance + 10000.0)) < 0.01)
            
            # Test 4: Recover from security state corruption
            # Corrupt user permissions
            user = self.db.get_user(self.test_user_id)
            original_permissions = user.permissions
            user.permissions = "INVALID_PERMISSIONS"
            self.db._save_user_raw(user)  # Bypass validation
            
            # Attempt operation (should trigger security recovery)
            result = self.api.get_account(self.auth_token, account_id)
            recovery_tests.append(result["success"] is True)
            
            # Check if permissions were restored
            recovered_user = self.db.get_user(self.test_user_id)
            recovery_tests.append(recovered_user.permissions == original_permissions)
            
            # Test 5: Recover from external dependency failure
            # Simulate external system failure and recovery
            with patch('requests.post', side_effect=[
                Exception("External system unavailable"),  # First call fails
                MagicMock(status_code=200, json=lambda: {"success": True})  # Second call succeeds
            ]):
                # Attempt operation that depends on external system
                result = self.api.process_external_payment(self.auth_token, {
                    "account_id": account_id,
                    "amount": 1000.0,
                    "payment_method": "credit_card"
                })
                
                recovery_tests.append(result["success"] is True)
            
            # Calculate success
            success = all(recovery_tests)
            
            return {
                "success": success,
                "metrics": [
                    {"name": "system_recovery", "value": sum(recovery_tests), "target": len(recovery_tests), "threshold": len(recovery_tests), "passed": success}
                ],
                "recovery_results": recovery_tests
            }
        except Exception as e:
            return {
                "success": False,
                "error": str(e)
            }
    
    def run_all_tests(self):
        """Run all error recovery tests"""
        test_funcs = {
            "database_connection_failures": self.test_database_connection_failures,
            "transaction_rollbacks": self.test_transaction_rollbacks,
            "api_error_handling": self.test_api_error_handling,
            "concurrent_operation_conflicts": self.test_concurrent_operation_conflicts,
            "system_recovery": self.test_system_recovery
        }
        
        results = self.framework.run_test_suite("error_recovery", test_funcs, "error_handling")
        return results


# Run tests if executed directly
if __name__ == "__main__":
    tests = ErrorRecoveryTests()
    results = tests.run_all_tests()
    
    # Generate and print report
    framework = tests.framework
    report = framework.generate_test_report("text")
    print(report["text_report"])
    
    # Export results
    framework.export_test_results("error_recovery_test_results.json")
    
    # Clean up
    framework.cleanup()

